Workbook

Sheet Todos negocios
A1: Nombre del negocio | B1: Etapa del negocio | C1: Valor | D1: =SUBTOTAL(9,C:C) -> 13800000
A2: L Catertton | B2: Serie A
A3: Creadev | B3: Serie A
A4: Paulina Orillac - ENLIGHTENED HOSPITALITY INVESTMENTS | B4: Serie A
A5: Brilia | B5: Posibles inversionistas | C5: 500000
A6: Misael Castillo - CEO Star TV México | B6: Posibles inversionistas | C6: 250000
A7: Jorge Lievano - Amigo Daniel Sardi | B7: Posibles inversionistas | C7: 250000
A8: Mauricio Hoyos | B8: Posibles inversionistas | C8: 250000
A9: Santiago Pardo | B9: Posibles inversionistas | C9: 500000
A10: Juan Emilio | B10: Contactado - Deck enviado | C10: 250000
A11: Freddy Vega - Platzi | B11: Contactado - Deck enviado | C11: 250000
A12: Mauricio Caicedo | B12: Contactado - Deck enviado | C12: 250000
A13: Roman Irrure | B13: Primer seguimiento | C13: 250000
A14: Matt Parkhurst | B14: Aceptación - Envio de documentos | C14: 250000
A15: Tom Noons | B15: Aceptación - Envio de documentos | C15: 250000
A16: Ignacio - Antonio Marin - Majaceites (España) | B16: Firma de documentos | C16: 500000
... A52: Ernesto de Lima | B52: Cierre perdido | C52: 250000

Sheet Output
A2: * | B2: Serie A | C2: =SUM(C3:C5) -> 0 | E2: Interés más adelante | F2: =SUM(F3:F14) -> 3600000 | H2: RESUMEN | K2: {=_xlfn.UNIQUE('Todos negocios'!B:B)} -> Etapa del negocio
B3: {=_xlfn.UNIQUE(_xlfn._xlws.FILTER('Todos negocios'!$A:$A,'Todos negocios'!$B:$B=B2))} -> L Catertton | C3: =_xlfn.XLOOKUP(B3,'Todos negocios'!$A:$A,'Todos negocios'!$C:$C) | E3: {=_xlfn.UNIQUE(_xlfn._xlws.FILTER('Todos negocios'!$A:$A,'Todos negocios'!$B:$B=E2))} -> Pablo Galante | F3: =_xlfn.XLOOKUP(E3,'Todos negocios'!$A:$A,'Todos negocios'!$C:$C) -> 250000 | H3: Serie A | I3: =SUMIFS($C:$C,$B:$B,H3) -> 0 | K3: Serie A | L3: =_xlfn.XLOOKUP(K3,Output!B:B,Output!B:B,"Incluir") -> Serie A
B4: Creadev | C4: =_xlfn.XLOOKUP(B4,'Todos negocios'!$A:$A,'Todos negocios'!$C:$C) | E4: Martin y Alvaro - Grupo Almodama | F4: =_xlfn.XLOOKUP(E4,'Todos negocios'!$A:$A,'Todos negocios'!$C:$C) -> 250000 | H4: Posibles inversionistas | I4: =SUMIFS($C:$C,$B:$B,H4) -> 1750000 | K4: Posibles inversionistas | L4: =_xlfn.XLOOKUP(K4,Output!B:B,Output!B:B,"Incluir") -> Posibles inversionistas
B5: Paulina Orillac - ENLIGHTENED HOSPITALITY INVESTMENTS | C5: =_xlfn.XLOOKUP(B5,'Todos negocios'!$A:$A,'Todos negocios'!$C:$C) | E5: Joaquin Niemann | F5: =_xlfn.XLOOKUP(E5,'Todos negocios'!$A:$A,'Todos negocios'!$C:$C) -> 500000 | H5: Contactado - Deck enviado | I5: =SUMIFS($C:$C,$B:$B,H5) -> 750000 | K5: Contactado - Deck enviado | L5: =_xlfn.XLOOKUP(K5,Output!B:B,Output!B:B,"Incluir") -> Contactado - Deck enviado
E6: Alfredo Angel Casas | F6: =_xlfn.XLOOKUP(E6,'Todos negocios'!$A:$A,'Todos negocios'!$C:$C) -> 250000 | H6: Primer seguimiento | I6: =SUMIFS($C:$C,$B:$B,H6) -> 250000 | K6: Primer seguimiento | L6: =_xlfn.XLOOKUP(K6,Output!B:B,Output!B:B,"Incluir") -> Primer seguimiento
A7: * | B7: Posibles inversionistas | C7: =SUM(C8:C12) -> 1750000 | E7: Juan Sebastian Muñoz | F7: =_xlfn.XLOOKUP(E7,'Todos negocios'!$A:$A,'Todos negocios'!$C:$C) -> 500000 | H7: Aceptación - Envio de documentos | I7: =SUMIFS($C:$C,$B:$B,H7) -> 500000 | K7: Aceptación - Envio de documentos | L7: =_xlfn.XLOOKUP(K7,Output!B:B,Output!B:B,"Incluir") -> Aceptación - Envio de documentos
B8: {=_xlfn.UNIQUE(_xlfn._xlws.FILTER('Todos negocios'!$A:$A,'Todos negocios'!$B:$B=B7))} -> Brilia | C8: =_xlfn.XLOOKUP(B8,'Todos negocios'!$A:$A,'Todos negocios'!$C:$C) -> 500000 | E8: Familia Carmona | F8: =_xlfn.XLOOKUP(E8,'Todos negocios'!$A:$A,'Todos negocios'!$C:$C) -> 250000 | H8: Firma de documentos | I8: =SUMIFS($C:$C,$B:$B,H8) -> 500000 | K8: Firma de documentos | L8: =_xlfn.XLOOKUP(K8,Output!B:B,Output!B:B,"Incluir") -> Firma de documentos
B9: Misael Castillo - CEO Star TV México | C9: =_xlfn.XLOOKUP(B9,'Todos negocios'!$A:$A,'Todos negocios'!$C:$C) -> 250000 | E9: Enrico Benedetti | F9: =_xlfn.XLOOKUP(E9,'Todos negocios'!$A:$A,'Todos negocios'!$C:$C) -> 250000 | H9: Seguimiento giro | I9: =SUMIFS($C:$C,$B:$B,H9) -> 0 | K9: Convertidos (Giro) | L9: =_xlfn.XLOOKUP(K9,Output!B:B,Output!B:B,"Incluir") -> Convertidos (Giro)
B10: Jorge Lievano - Amigo Daniel Sardi | C10: =_xlfn.XLOOKUP(B10,'Todos negocios'!$A:$A,'Todos negocios'!$C:$C) -> 250000 | E10: Francisco Diaz | F10: =_xlfn.XLOOKUP(E10,'Todos negocios'!$A:$A,'Todos negocios'!$C:$C) -> 250000 | H10: Convertidos (Giro) | I10: =SUMIFS($C:$C,$B:$B,H10) -> 3700000 | K10: Interés más adelante
B11: Mauricio Hoyos | C11: =_xlfn.XLOOKUP(B11,'Todos negocios'!$A:$A,'Todos negocios'!$C:$C) -> 250000 | E11: Ignacio (Agrogonzamex), contacto Daniel Sardi | F11: =_xlfn.XLOOKUP(E11,'Todos negocios'!$A:$A,'Todos negocios'!$C:$C) -> 250000 | K11: Cierre perdido
B12: Santiago Pardo | C12: =_xlfn.XLOOKUP(B12,'Todos negocios'!$A:$A,'Todos negocios'!$C:$C) -> 500000 | E12: Camilo Higuera | F12: =_xlfn.XLOOKUP(E12,'Todos negocios'!$A:$A,'Todos negocios'!$C:$C) -> 250000 | K12: 0
E13: Familia Liechtenstein | F13: =_xlfn.XLOOKUP(E13,'Todos negocios'!$A:$A,'Todos negocios'!$C:$C) -> 250000
A14: * | B14: Contactado - Deck enviado | C14: =SUM(C15:C17) -> 750000 | E14: Diego Sardi - Ventolini | F14: =_xlfn.XLOOKUP(E14,'Todos negocios'!$A:$A,'Todos negocios'!$C:$C) -> 350000
B15: {=_xlfn.UNIQUE(_xlfn._xlws.FILTER('Todos negocios'!$A:$A,'Todos negocios'!$B:$B=B14))} -> Juan Emilio | C15: =_xlfn.XLOOKUP(B15,'Todos negocios'!$A:$A,'Todos negocios'!$C:$C) -> 250000
B16: Freddy Vega - Platzi | C16: =_xlfn.XLOOKUP(B16,'Todos negocios'!$A:$A,'Todos negocios'!$C:$C) -> 250000 | E16: Cierre perdido | F16: =SUM(F17:F27) -> 2750000
B17: Mauricio Caicedo | C17: =_xlfn.XLOOKUP(B17,'Todos negocios'!$A:$A,'Todos negocios'!$C:$C) -> 250000 | E17: {=_xlfn.UNIQUE(_xlfn._xlws.FILTER('Todos negocios'!$A:$A,'Todos negocios'!$B:$B=E16))} -> Jorge Eduardo Leon (Tato) | F17: =_xlfn.XLOOKUP(E17,'Todos negocios'!$A:$A,'Todos negocios'!$C:$C) -> 250000
E18: Juan Carlos Valencia | F18: =_xlfn.XLOOKUP(E18,'Todos negocios'!$A:$A,'Todos negocios'!$C:$C) -> 250000
A19: * | B19: Primer seguimiento | C19: =SUM(C20) -> 250000 | E19: Paola y Marcela Sardi | F19: =_xlfn.XLOOKUP(E19,'Todos negocios'!$A:$A,'Todos negocios'!$C:$C) -> 250000
B20: {=_xlfn.UNIQUE(_xlfn._xlws.FILTER('Todos negocios'!$A:$A,'Todos negocios'!$B:$B=B19))} -> Roman Irrure | C20: =_xlfn.XLOOKUP(B20,'Todos negocios'!$A:$A,'Todos negocios'!$C:$C) -> 250000 | E20: Nicolas Largacha, contacto Daniel Sardi | F20: =_xlfn.XLOOKUP(E20,'Todos negocios'!$A:$A,'Todos negocios'!$C:$C) -> 250000
E21: Timothy Ngo | F21: =_xlfn.XLOOKUP(E21,'Todos negocios'!$A:$A,'Todos negocios'!$C:$C) -> 250000
A22: * | B22: Aceptación - Envio de documentos | C22: =SUM(C23:C24) -> 500000 | E22: Todd (YPO) | F22: =_xlfn.XLOOKUP(E22,'Todos negocios'!$A:$A,'Todos negocios'!$C:$C) -> 250000
B23: {=_xlfn.UNIQUE(_xlfn._xlws.FILTER('Todos negocios'!$A:$A,'Todos negocios'!$B:$B=B22))} -> Matt Parkhurst | C23: =_xlfn.XLOOKUP(B23,'Todos negocios'!$A:$A,'Todos negocios'!$C:$C) -> 250000 | E23: Arash (YPO) | F23: =_xlfn.XLOOKUP(E23,'Todos negocios'!$A:$A,'Todos negocios'!$C:$C) -> 250000
B24: Tom Noons | C24: =_xlfn.XLOOKUP(B24,'Todos negocios'!$A:$A,'Todos negocios'!$C:$C) -> 250000 | E24: Carlos Alberto Rodriguez - Contacto Daniel Sardi | F24: =_xlfn.XLOOKUP(E24,'Todos negocios'!$A:$A,'Todos negocios'!$C:$C) -> 250000
E25: Oficina de familia en India - Lisa | F25: =_xlfn.XLOOKUP(E25,'Todos negocios'!$A:$A,'Todos negocios'!$C:$C) -> 250000
A26: * | B26: Firma de documentos | C26: =SUM(C27:C29) -> 500000 | E26: Jacinto Luna | F26: =_xlfn.XLOOKUP(E26,'Todos negocios'!$A:$A,'Todos negocios'!$C:$C) -> 250000
B27: {=_xlfn.UNIQUE(_xlfn._xlws.FILTER('Todos negocios'!$A:$A,'Todos negocios'!$B:$B=B26))} -> Ignacio - Antonio Marin - Majaceites (España) | C27: =_xlfn.XLOOKUP(B27,'Todos negocios'!$A:$A,'Todos negocios'!$C:$C) -> 500000 | E27: Ernesto de Lima | F27: =_xlfn.XLOOKUP(E27,'Todos negocios'!$A:$A,'Todos negocios'!$C:$C) -> 250000
E29: TOTAL PERDIDOS | F29: =F2+F16 -> 6350000
A30: * | B30: Seguimiento giro | C30: =SUM(C31:C31) -> 0
A33: * | B33: Convertidos (Giro) | C33: =SUM(C34:C46) -> 3700000
B34: {=_xlfn.UNIQUE(_xlfn._xlws.FILTER('Todos negocios'!$A:$A,'Todos negocios'!$B:$B=B33))} -> Andrés Uribe y Pablo Sardi | C34: =_xlfn.XLOOKUP(B34,'Todos negocios'!$A:$A,'Todos negocios'!$C:$C) -> 250000
B35: Cesar Moreyra | C35: =_xlfn.XLOOKUP(B35,'Todos negocios'!$A:$A,'Todos negocios'!$C:$C) -> 250000
B36: Pablo Querubin & Claudia Linares | C36: =_xlfn.XLOOKUP(B36,'Todos negocios'!$A:$A,'Todos negocios'!$C:$C) -> 250000
B37: Marcial Gonzalez | C37: =_xlfn.XLOOKUP(B37,'Todos negocios'!$A:$A,'Todos negocios'!$C:$C) -> 200000 | H37: =F29+C48-'Todos negocios'!D1 -> 0 | I37: =SUM(I3:I10)-C48 -> 0
B38: Olallo Villoldo - Amigo España | C38: =_xlfn.XLOOKUP(B38,'Todos negocios'!$A:$A,'Todos negocios'!$C:$C) -> 500000
B39: Armando Sardi | C39: =_xlfn.XLOOKUP(B39,'Todos negocios'!$A:$A,'Todos negocios'!$C:$C) -> 250000
B40: Alberto Francis y Dillon | C40: =_xlfn.XLOOKUP(B40,'Todos negocios'!$A:$A,'Todos negocios'!$C:$C) -> 250000
B41: Nicolás Kling - Invernicho | C41: =_xlfn.XLOOKUP(B41,'Todos negocios'!$A:$A,'Todos negocios'!$C:$C) -> 250000
B42: Pablo Madriñan | C42: =_xlfn.XLOOKUP(B42,'Todos negocios'!$A:$A,'Todos negocios'!$C:$C) -> 250000
B43: Madvil Venture - Alvaro Madriñan | C43: =_xlfn.XLOOKUP(B43,'Todos negocios'!$A:$A,'Todos negocios'!$C:$C) -> 500000
B44: Henry Medina - Maximae Vision | C44: =_xlfn.XLOOKUP(B44,'Todos negocios'!$A:$A,'Todos negocios'!$C:$C) -> 250000
...
